Workbook
Name _BR167: 'Parts List and Volumes'!$C$70:$C$105
Name _R1S: 'Parts List and Volumes'!$C$144:$C$147
Name _R1S_T: 'Parts List and Volumes'!$C$136:$C$139
Name _R1T: 'Parts List and Volumes'!$C$140:$C$143
Name _VN127: 'Parts List and Volumes'!$C$2:$C$28
Name EVAII: 'Parts List and Volumes'!$C$54:$C$69
Name F5X: 'Parts List and Volumes'!$C$29:$C$53
Name FourHeadAssumption: Assumptions!$A$19
Name G01_G02: 'Parts List and Volumes'!$C$114:$C$123
Name G05_G06: 'Parts List and Volumes'!$C$132:$C$133
Name G05_G06_G07: 'Parts List and Volumes'!$C$124:$C$131
Name G05_G06_G07_G09: 'Parts List and Volumes'!$C$106:$C$113
Name G07_G09: 'Parts List and Volumes'!$C$134:$C$135
Name RPV_500: 'Parts List and Volumes'!$C$161:$C$176
Name RPV_500_700_900: 'Parts List and Volumes'!$C$153:$C$160
Name RPV_700: 'Parts List and Volumes'!$C$171:$C$172
Name RPV_700_900: 'Parts List and Volumes'!$C$148:$C$152
Name SingleEndAssumption: Assumptions!$G$19

Sheet Assumptions
A1: CNC - Dengler Capacity Assumptions - Planning | G1: CNC - Wafios Capacity Assumptions - Planning
A2: =7.5*60*60 -> 27000 | B2: seconds | C2: Maximum run time per shift - breaks (7.5 hours) | G2: =7.5*60*60 -> 27000 | H2: seconds | I2: Maximum run time per shift - breaks (7.5 hours)
A3: 0.85 | B3: percent | C3: Expected/Planned Efficiency (with PFD) | G3: 0.85 | H3: percent | I3: Expected/Planned Efficiency (with PFD)
A4: 15 | B4: shifts | C4: shifts per week (some customers want to see 10 shifts) | G4: 15 | H4: shifts | I4: shifts per week (some customers want to see 10 shifts)
A5: 48 | B5: Weeks | C5: weeks per year | G5: 48 | H5: Weeks | I5: weeks per year
A6: Plan for: | G6: Plan for:
A7: 2400 | B7: seconds | C7: Change over per shift 2 @ 20 minutes | G7: 1200 | H7: seconds | I7: Change over per shift 2 @ 10 minutes
A8: 600 | B8: seconds | C8: 10 minute cleanup and TPM 10 min | G8: 600 | H8: seconds | I8: 10 minute cleanup and TPM 10 min
A9: 300 | B9: seconds | C9: Shift meeting 5 min | G9: 300 | H9: seconds | I9: Shift meeting 5 min
A10: 0 | B10: seconds | C10: Preventative Maintenance Time (2 PM's per month @ 8 hrs). | G10: 0 | H10: seconds | I10: Preventative Maintenance Time (2 PM's per month @ 8 hrs).
A11: 300 | B11: seconds | C11: Averaged Equipment Emerg. Downtime | G11: 300 | H11: seconds | I11: Averaged Equipment Emerg. Downtime
A12: 600 | B12: seconds | C12: Bad tube/material average - sporadic / no good data | G12: 300 | H12: seconds | I12: Bad tube/material average - sporadic / no good data
A14: 600 | B14: seconds | C14: Time alloted for quality checks (10 min) | G14: 300 | H14: seconds | I14: Time alloted for quality checks (5 min)
A15: =SUM(A7:A14) -> 4800 | B15: seconds | C15: Total non run-time per shift | G15: =SUM(G7:G14) -> 3000 | H15: seconds | I15: Total non run-time per shift
A18: =A2-A15 -> 22200 | B18: seconds | C18: Seconds available per shift | G18: =G2-G15 -> 24000 | H18: seconds | I18: Seconds available per shift
A19: =A18*A4*A5*A3 -> 13586400 | B19: seconds | C19: Seconds of run time available per year | G19: =G18*G4*G5*G3 -> 14688000

Sheet Parts List and Volumes
A1: Customer | B1: Customer Program | C1: Customer Part Number | D1: Internal TI Part Number | E1: Tube Diameter | F1: # of Bends | G1: 2022 Actual | H1: 2022 Quoted | I1: 2023 Actual | J1: 2023 Quoted | K1: 2024 Actual | L1: 2024 Quoted | M1: 2025 Actual | N1: 2025 Quoted | O1: 2026 Actual | P1: 2026 Quoted | Q1: 2027 Actual | R1: 2027 Quoted | S1: 2028 Actual | T1: 2028 Quoted | U1: 2029 Actual | V1: 2029 Quoted | W1: 2030 Actual | X1: 2030 Quoted
A2: Ford | B2: _VN127 | C2: LC24 2263 AA | D2: NE000268AAF20 | E2: 4.76 | G2: 53118 | H2: 68640 | J2: 68640 | L2: 68640 | N2: 68640 | P2: 68640 | R2: 0 | T2: 0 | V2: 0 | X2: 0
A3: Ford | B3: _VN127 | C3: LC24 2264 AA | D3: NE000269AAF20 | E3: 4.76 | G3: 53797 | H3: 68640 | J3: 68640 | L3: 68640 | N3: 68640 | P3: 68640 | R3: 0 | T3: 0 | V3: 0 | X3: 0
A4: Ford | B4: _VN127 | C4: LC24 2234 AC | D4: NF000862ACF20 | E4: 4.76 | G4: 5416 | H4: 4804.8 | J4: 4804.8 | L4: 4804.8 | N4: 4804.8 | P4: 4804.8 | R4: 0 | T4: 0 | V4: 0 | X4: 0
A5: Ford | B5: _VN127 | C5: LC24 2234 BC | D5: NF000863ACF20 | E5: 4.76 | G5: 5411 | H5: 4804.8 | J5: 4804.8 | L5: 4804.8 | N5: 4804.8 | P5: 4804.8 | R5: 0 | T5: 0 | V5: 0 | X5: 0
A6: Ford | B6: _VN127 | C6: LC24 2234 CC | D6: NF000864ACF20 | E6: 4.76 | G6: 44095 | H6: 68640 | J6: 68640 | L6: 68640 | N6: 68640 | P6: 68640 | R6: 0 | T6: 0 | V6: 0 | X6: 0
A7: Ford | B7: _VN127 | C7: LC24 2234 DC | D7: NF000865ACF20 | E7: 4.76 | G7: 43827 | H7: 68640 | J7: 68640 | L7: 68640 | N7: 68640 | P7: 68640 | R7: 0 | T7: 0 | V7: 0 | X7: 0
A8: Ford | B8: _VN127 | C8: LC24 2234 EC | D8: NF000866ABF20 | E8: 4.76 | G8: 2545 | H8: 4804.8 | J8: 4804.8 | L8: 4804.8 | N8: 4804.8 | P8: 4804.8 | R8: 0 | T8: 0 | V8: 0 | X8: 0
A9: Ford | B9: _VN127 | C9: LC24 2234 FB | D9: NF000867ABF20 | E9: 4.76 | G9: 2545 | H9: 4804.8 | J9: 4804.8 | L9: 4804.8 | N9: 4804.8 | P9: 4804.8 | R9: 0 | T9: 0 | V9: 0 | X9: 0
A10: Ford | B10: _VN127 | C10: LC24 9G700 AD | D10: NI000618ACF20 | E10: 4.76 | G10: 7000 | H10: 9952.8 | J10: 9952.8 | L10: 9952.8 | N10: 9952.8 | P10: 9952.8 | R10: 0 | T10: 0 | V10: 0 | X10: 0
A11: Ford | B11: _VN127 | C11: LC24 9G700 BE | D11: NI000619ADF20 | E11: 4.76 | G11: 8293 | H11: 16473.6 | J11: 16473.6 | L11: 16473.6 | N11: 16473.6 | P11: 16473.6 | R11: 0 | T11: 0 | V11: 0 | X11: 0
A12: Ford | B12: _VN127 | C12: LC24 9G700 CE | D12: NI000620ADF20 | E12: 4.76 | G12: 6062 | H12: 6177.6 | J12: 6177.6 | L12: 6177.6 | N12: 6177.6 | P12: 6177.6 | R12: 0 | T12: 0 | V12: 0 | X12: 0
A13: Ford | B13: _VN127 | C13: LC24 9G700 DD | D13: NI000621ACF20 | E13: 4.76 | G13: 2248 | H13: 0 | J13: 0 | L13: 0 | N13: 0 | P13: 0 | R13: 0 | T13: 0 | V13: 0 | X13: 0
... A22: Ford | B22: _VN127 | C22: LC24 2C017 BA | D22: NJ000154AAF20 | E22: 4.76 | G22: 2547 | H22: 4804.8 | J22: 4804.8 | L22: 4804.8 | N22: 4804.8 | P22: 4804.8 | R22: 0 | T22: 0 | V22: 0 | X22: 0
A23: Ford | B23: _VN127 | C23: 9C24 9S296 DD | D23: PA000413ABF20 | G23: 21869 | H23: 31574.4 | J23: 31574.4 | L23: 31574.4 | N23: 31574.4 | P23: 31574.4 | R23: 0 | T23: 0 | V23: 0 | X23: 0
A24: Ford | B24: _VN127 | C24: 9C24 9S296 ED | D24: PA000414ABF20 | G24: 26605 | H24: 3432 | J24: 3432 | L24: 3432 | N24: 3432 | P24: 3432 | R24: 0 | T24: 0 | V24: 0 | X24: 0
A25: Ford | B25: _VN127 | C25: LC24 9G291 AB | D25: PE000117AAF20 | G25: 53624 | H25: 68640 | J25: 68640 | L25: 68640 | N25: 68640 | P25: 68640 | R25: 0 | T25: 0 | V25: 0 | X25: 0
A26: Ford | B26: _VN127 | C26: LC24 9S296 AA | D26: PF000127AAF20 | G26: 2945 | H26: 2333.76 | J26: 2333.76 | L26: 2333.76 | N26: 2333.76 | P26: 2333.76 | R26: 0 | T26: 0 | V26: 0 | X26: 0
A27: Ford | B27: _VN127 | C27: LC24 9S296 BA | D27: PF000128AAF20 | G27: 2050 | H27: 960.96 | J27: 960.96 | L27: 960.96 | N27: 960.96 | P27: 960.96 | R27: 0 | T27: 0 | V27: 0 | X27: 0
A28: Ford | B28: _VN127 | C28: LC24 9B050 AB | D28: PK000445ABF20 | G28: 28242 | H28: 51480 | J28: 51480 | L28: 51480 | N28: 51480 | P28: 51480 | R28: 0 | T28: 0 | V28: 0 | X28: 0
A29: Ford | B29: F5X | C29: BU94 9C047 AC | D29: PA000421ABF20 | G29: 15781 | H29: 22440 | J29: 22440 | L29: 22440 | N29: 22440 | P29: 0 | R29: 0 | T29: 0 | V29: 0 | X29: 0
A30: Ford | B30: F5X | C30: BU94 9C047 BC | D30: PA000422ABF20 | G30: 13524 | H30: 2087 | J30: 2087 | L30: 2087 | N30: 2087 | P30: 0 | R30: 0 | T30: 0 | V30: 0 | X30: 0
A31: Ford | B31: F5X | C31: CU94 9S273 BB | D31: PA008811ABF20 | G31: 13823 | H31: 2087 | J31: 2087 | L31: 2087 | N31: 2087 | P31: 0 | R31: 0 | T31: 0 | V31: 0 | X31: 0
A32: Ford | B32: F5X | C32: GU94 9A322 JB | D32: PE000089AAF20 | G32: 3291 | H32: 98 | J32: 98 | L32: 98 | N32: 98 | P32: 0 | R32: 0 | T32: 0 | V32: 0 | X32: 0
A33: Ford | B33: F5X | C33: LU94 9G321 BA | D33: PE000118AAF20 | G33: 2913 | H33: 1104 | J33: 1104 | L33: 1104 | N33: 1104 | P33: 0 | R33: 0 | T33: 0 | V33: 0 | X33: 0
A34: Ford | B34: F5X | C34: LU94 9G321 CA | D34: PE000119AAF20 | G34: 5713 | H34: 4420 | J34: 4420 | L34: 4420 | N34: 4420 | P34: 0 | R34: 0 | T34: 0 | V34: 0 | X34: 0
... A104: Mercedes | B104: BR167 | C104: A167 470 48 04 | D104: NF020655AAF20 | G104: 3 | H104: 49310.308 | J104: 44943.325 | L104: 39708.978 | N104: 32745.934 | P104: 6785.3094 | R104: 0 | T104: 0 | V104: 0 | X104: 0
A105: Mercedes | B105: BR167 | C105: A167 470 52 04 | D105: NF020659AAF20 | G105: 5400 | H105: 11772.192 | I105: 3776 | J105: 10729.632 | L105: 9480 | N105: 7817.664 | P105: 1619.904 | R105: 0 | T105: 0 | V105: 0 | X105: 0
A106: BMW | B106: G05_G06_G07_G09 | C106: 7-915-325-02 | D106: NFAA1610AAF20 | E106: 4.76 | G106: 23204 | H106: 22637 | I106: 22637 | J106: 22637 | L106: 238306 | N106: 238306 | P106: 0 | R106: 0 | T106: 0 | V106: 0 | X106: 0
A107: BMW | B107: G05_G06_G07_G09 | C107: 7-915-327-03 | D107: NFAA1611AAF20 | E107: 4.76 | G107: 0 | H107: 22637 | I107: 22637 | J107: 22637 | L107: 238306 | N107: 238306 | P107: 0 | R107: 0 | T107: 0 | V107: 0 | X107: 0
A108: BMW | B108: G05_G06_G07_G09 | C108: 7-915-329-01 | D108: NFAA1612AAF20 | E108: 4.76 | G108: 23204 | H108: 22637 | I108: 22637 | J108: 22637 | L108: 238306 | N108: 238306 | P108: 0 | R108: 0 | T108: 0 | V108: 0 | X108: 0
A109: BMW | B109: G05_G06_G07_G09 | C109: 7-915-331-02 | D109: NFAA1617AAF20 | E109: 4.76 | G109: 23204 | H109: 22637 | I109: 22637 | J109: 22637 | L109: 238306 | N109: 238306 | P109: 0 | R109: 0 | T109: 0 | V109: 0 | X109: 0
A110: BMW | B110: G05_G06_G07_G09 | C110: 7-915-333-02 | D110: NFAA1618AAF20 | E110: 4.76 | G110: 1036 | H110: 1014 | I110: 1014 | J110: 1014 | L110: 24773 | N110: 24773 | P110: 0 | R110: 0 | T110: 0 | V110: 0 | X110: 0
A111: BMW | B111: G05_G06_G07_G09 | C111: 7-915-335-02 | D111: NFAA1619AAF20 | E111: 4.76 | G111: 1036 | H111: 1014 | I111: 1014 | J111: 1014 | L111: 24773 | N111: 24773 | P111: 0 | R111: 0 | T111: 0 | V111: 0 | X111: 0
A112: BMW | B112: G05_G06_G07_G09 | C112: 7-915-337-01 | D112: NFAA1620AAF20 | E112: 4.76 | G112: 1036 | H112: 1014 | I112: 1014 | J112: 1014 | L112: 24773 | N112: 24773 | P112: 0 | R112: 0 | T112: 0 | V112: 0 | X112: 0
A113: BMW | B113: G05_G06_G07_G09 | C113: 7-915-339-01 | D113: NFAA1621AAF20 | E113: 4.76 | G113: 1036 | H113: 1014 | I113: 1014 | J113: 1014 | L113: 24773 | N113: 24773 | P113: 0 | R113: 0 | T113: 0 | V113: 0 | X113: 0
A114: BMW | B114: G01_G02 | C114: 6-871-435-01 | D114: NFAA0187AAF20 | E114: 4.76 | G114: 168369 | H114: 167238 | I114: 167238 | J114: 167238 | L114: 85956 | N114: 0 | P114: 0 | R114: 0 | T114: 0 | V114: 0 | X114: 0
A115: BMW | B115: G01_G02 | C115: 6-871-439-03 | D115: NFAA0189ACF20 | E115: 4.76 | G115: 170373 | H115: 169500 | I115: 169500 | J115: 169500 | L115: 85956 | N115: 0 | P115: 0 | R115: 0 | T115: 0 | V115: 0 | X115: 0
A116: BMW | B116: G01_G02 | C116: 6-871-441-03 | D116: NFAA0190ACF20 | E116: 4.76 | G116: 170291 | H116: 169605 | I116: 169605 | J116: 169605 | L116: 85956 | N116: 0 | P116: 0 | R116: 0 | T116: 0 | V116: 0 | X116: 0
A117: BMW | B117: G01_G02 | C117: 6-874-633-01 | D117: NFAA0195AAF20 | G117: 10421 | H117: 10425 | I117: 10425 | J117: 10425 | L117: 17191 | N117: 0 | P117: 0 | R117: 0 | T117: 0 | V117: 0 | X117: 0
...

Sheet Master Sheet
A1: CNC Machine # | G1: 2022 | K1: 2023 | O1: 2024 | S1: 2025 | W1: 2026 | AA1: 2027 | AE1: 2028 | AI1: 2029 | AM1: 2030 | AQ1: 2031 | AU1: 2032
A2: Customer Part Number | B2: Platform | C2: TI Part Number | D2: Tube Diamter | E2: # of Bends | F2: cyc time | G2: Actual Volume | H2: Customer Quoted Vol | I2: % to Actual | J2: % to Tool Note | K2: Actual Volume | L2: Customer Quoted Vol | M2: % to Actual | N2: % to Tool Note | O2: Actual Volume | P2: Customer Quoted Vol | Q2: % to Actual | R2: % to Tool Note | S2: Actual Volume | T2: Customer Quoted Vol | U2: % to Actual | V2: % to Tool Note | W2: Actual Volume | X2: Customer Quoted Vol | Y2: % to Actual | Z2: % to Tool Note | AA2: Actual Volume | AB2: Customer Quoted Vol | AC2: % to Actual | AD2: % to Tool Note | AE2: Actual Volume | AF2: Customer Quoted Vol | AG2: % to Actual | AH2: % to Tool Note | AI2: Actual Volume | AJ2: Customer Quoted Vol | AK2: % to Actual | AL2: % to Tool Note | AM2: Actual Volume | AN2: Customer Quoted Vol | AO2: % to Actual | AP2: % to Tool Note | AQ2: Actual Volume | AR2: Customer Quoted Vol | AS2: % to Actual | AT2: % to Tool Note | AU2: Actual Volume | AV2: Customer Quoted Vol | AW2: % to Actual | AX2: % to Tool Note
C3: =IFERROR(VLOOKUP(A3,'Parts List and Volumes'!C2:D194,2,FALSE),"") | D3: =IFERROR(IF(VLOOKUP($A3,'Parts List and Volumes'!$C2:$F266,3,FALSE)=0,"",VLOOKUP(A3,'Parts List and Volumes'!C2:F266,3,FALSE)),"") | E3: =IFERROR(IF(VLOOKUP($A3,'Parts List and Volumes'!$C2:$F266,4,FALSE)=0,"",VLOOKUP(B3,'Parts List and Volumes'!D2:G266,3,FALSE)),"") | G3: =IFERROR(VLOOKUP($A3,'Parts List and Volumes'!$C$2:$W194,5,FALSE),"") | H3: =IFERROR(VLOOKUP($A3,'Parts List and Volumes'!$C$2:$W194,6,FALSE),"") | I3: =IFERROR((($F3*G3)/FourHeadAssumption),"") | J3: =IFERROR((($F3*H3)/FourHeadAssumption),"") | K3: =IFERROR(VLOOKUP($A3,'Parts List and Volumes'!$C$2:$W194,7,FALSE),"") | L3: =IFERROR(VLOOKUP($A3,'Parts List and Volumes'!$C$2:$W194,8,FALSE),"") | M3: =IFERROR((($F3*K3)/FourHeadAssumption),"") | N3: =IFERROR((($F3*L3)/FourHeadAssumption),"") | O3: =IFERROR(VLOOKUP($A3,'Parts List and Volumes'!$C$2:$W194,9,FALSE),"") | P3: =IFERROR(VLOOKUP($A3,'Parts List and Volumes'!$C$2:$W194,10,FALSE),"") | Q3: =IFERROR((($F3*O3)/FourHeadAssumption),"") | R3: =IFERROR((($F3*P3)/FourHeadAssumption),"") | S3: =IFERROR(VLOOKUP($A3,'Parts List and Volumes'!$C$2:$W194,11,FALSE),"") | T3: =IFERROR(VLOOKUP($A3,'Parts List and Volumes'!$C$2:$W194,12,FALSE),"") | U3: =IFERROR((($F3*S3)/FourHeadAssumption),"") | V3: =IFERROR((($F3*T3)/FourHeadAssumption),"") | W3: =IFERROR(VLOOKUP($A3,'Parts List and Volumes'!$C$2:$W194,13,FALSE),"") | X3: =IFERROR(VLOOKUP($A3,'Parts List and Volumes'!$C$2:$W194,14,FALSE),"") | Y3: =IFERROR((($F3*W3)/FourHeadAssumption),"") | Z3: =IFERROR((($F3*X3)/FourHeadAssumption),"") | AA3: =IFERROR(VLOOKUP($A3,'Parts List and Volumes'!$C$2:$W194,15,FALSE),"") | AB3: =IFERROR(VLOOKUP($A3,'Parts List and Volumes'!$C$2:$W194,16,FALSE),"") | AC3: =IFERROR((($F3*AA3)/FourHeadAssumption),"") | AD3: =IFERROR((($F3*AB3)/FourHeadAssumption),"") | AE3: =IFERROR(VLOOKUP($A3,'Parts List and Volumes'!$C$2:$W194,17,FALSE),"") | AF3: =IFERROR(VLOOKUP($A3,'Parts List and Volumes'!$C$2:$W194,18,FALSE),"") | AG3: =IFERROR((($F3*AE3)/FourHeadAssumption),"") | AH3: =IFERROR((($F3*AF3)/FourHeadAssumption),"") | AI3: =IFERROR(VLOOKUP($A3,'Parts List and Volumes'!$C$2:$W194,19,FALSE),"") | AJ3: =IFERROR(VLOOKUP($A3,'Parts List and Volumes'!$C$2:$W194,20,FALSE),"") | AK3: =IFERROR((($F3*AI3)/FourHeadAssumption),"") | AL3: =IFERROR((($F3*AJ3)/FourHeadAssumption),"") | AM3: =IFERROR(VLOOKUP($A3,'Parts List and Volumes'!$C$2:$W194,21,FALSE),"") | AN3: =IFERROR(VLOOKUP($A3,'Parts List and Volumes'!$C$2:$W194,22,FALSE),"") | AO3: =IFERROR((($F3*AM3)/FourHeadAssumption),"") | AP3: =IFERROR((($F3*AN3)/FourHeadAssumption),"") | AQ3: =IFERROR(VLOOKUP($A3,'Parts List and Volumes'!$C$2:$W194,23,FALSE),"") | AR3: =IFERROR(VLOOKUP($A3,'Parts List and Volumes'!$C$2:$W194,24,FALSE),"") | AS3: =IFERROR((($F3*AQ3)/FourHeadAssumption),"") | AT3: =IFERROR((($F3*AR3)/FourHeadAssumption),"") | AU3: =IFERROR(VLOOKUP($A3,'Parts List and Volumes'!$C$2:$W194,25,FALSE),"") | AV3: =IFERROR(VLOOKUP($A3,'Parts List and Volumes'!$C$2:$W194,26,FALSE),"") | AW3: =IFERROR((($F3*AU3)/FourHeadAssumption),"") | AX3: =IFERROR((($F3*AV3)/FourHeadAssumption),"")
C4: =IFERROR(VLOOKUP(A4,'Parts List and Volumes'!C3:D195,2,FALSE),"") | D4: =IFERROR(IF(VLOOKUP($A4,'Parts List and Volumes'!$C3:$F266,3,FALSE)=0,"",VLOOKUP(A4,'Parts List and Volumes'!C3:F266,3,FALSE)),"") | E4: =IFERROR(IF(VLOOKUP($A4,'Parts List and Volumes'!$C3:$F266,4,FALSE)=0,"",VLOOKUP(B4,'Parts List and Volumes'!D3:G266,3,FALSE)),"") | G4: =IFERROR(VLOOKUP($A4,'Parts List and Volumes'!$C$2:$W195,5,FALSE),"") | H4: =IFERROR(VLOOKUP($A4,'Parts List and Volumes'!$C$2:$W195,6,FALSE),"") | I4: =IFERROR((($F4*G4)/FourHeadAssumption),"") | J4: =IFERROR((($F4*H4)/FourHeadAssumption),"") | K4: =IFERROR(VLOOKUP($A4,'Parts List and Volumes'!$C$2:$W195,7,FALSE),"") | L4: =IFERROR(VLOOKUP($A4,'Parts List and Volumes'!$C$2:$W195,8,FALSE),"") | M4: =IFERROR((($F4*K4)/FourHeadAssumption),"") | N4: =IFERROR((($F4*L4)/FourHeadAssumption),"") | O4: =IFERROR(VLOOKUP($A4,'Parts List and Volumes'!$C$2:$W195,9,FALSE),"") | P4: =IFERROR(VLOOKUP($A4,'Parts List and Volumes'!$C$2:$W195,10,FALSE),"") | Q4: =IFERROR((($F4*O4)/FourHeadAssumption),"") | R4: =IFERROR((($F4*P4)/FourHeadAssumption),"") | S4: =IFERROR(VLOOKUP($A4,'Parts List and Volumes'!$C$2:$W195,11,FALSE),"") | T4: =IFERROR(VLOOKUP($A4,'Parts List and Volumes'!$C$2:$W195,12,FALSE),"") | U4: =IFERROR((($F4*S4)/FourHeadAssumption),"") | V4: =IFERROR((($F4*T4)/FourHeadAssumption),"") | W4: =IFERROR(VLOOKUP($A4,'Parts List and Volumes'!$C$2:$W195,13,FALSE),"") | X4: =IFERROR(VLOOKUP($A4,'Parts List and Volumes'!$C$2:$W195,14,FALSE),"") | Y4: =IFERROR((($F4*W4)/FourHeadAssumption),"") | Z4: =IFERROR((($F4*X4)/FourHeadAssumption),"") | AA4: =IFERROR(VLOOKUP($A4,'Parts List and Volumes'!$C$2:$W195,15,FALSE),"") | AB4: =IFERROR(VLOOKUP($A4,'Parts List and Volumes'!$C$2:$W195,16,FALSE),"") | AC4: =IFERROR((($F4*AA4)/FourHeadAssumption),"") | AD4: =IFERROR((($F4*AB4)/FourHeadAssumption),"") | AE4: =IFERROR(VLOOKUP($A4,'Parts List and Volumes'!$C$2:$W195,17,FALSE),"") | AF4: =IFERROR(VLOOKUP($A4,'Parts List and Volumes'!$C$2:$W195,18,FALSE),"") | AG4: =IFERROR((($F4*AE4)/FourHeadAssumption),"") | AH4: =IFERROR((($F4*AF4)/FourHeadAssumption),"") | AI4: =IFERROR(VLOOKUP($A4,'Parts List and Volumes'!$C$2:$W195,19,FALSE),"") | AJ4: =IFERROR(VLOOKUP($A4,'Parts List and Volumes'!$C$2:$W195,20,FALSE),"") | AK4: =IFERROR((($F4*AI4)/FourHeadAssumption),"") | AL4: =IFERROR((($F4*AJ4)/FourHeadAssumption),"") | AM4: =IFERROR(VLOOKUP($A4,'Parts List and Volumes'!$C$2:$W195,21,FALSE),"") | AN4: =IFERROR(VLOOKUP($A4,'Parts List and Volumes'!$C$2:$W195,22,FALSE),"") | AO4: =IFERROR((($F4*AM4)/FourHeadAssumption),"") | AP4: =IFERROR((($F4*AN4)/FourHeadAssumption),"") | AQ4: =IFERROR(VLOOKUP($A4,'Parts List and Volumes'!$C$2:$W195,23,FALSE),"") | AR4: =IFERROR(VLOOKUP($A4,'Parts List and Volumes'!$C$2:$W195,24,FALSE),"") | AS4: =IFERROR((($F4*AQ4)/FourHeadAssumption),"") | AT4: =IFERROR((($F4*AR4)/FourHeadAssumption),"") | AU4: =IFERROR(VLOOKUP($A4,'Parts List and Volumes'!$C$2:$W195,25,FALSE),"") | AV4: =IFERROR(VLOOKUP($A4,'Parts List and Volumes'!$C$2:$W195,26,FALSE),"") | AW4: =IFERROR((($F4*AU4)/FourHeadAssumption),"") | AX4: =IFERROR((($F4*AV4)/FourHeadAssumption),"")
C5: =IFERROR(VLOOKUP(A5,'Parts List and Volumes'!C4:D196,2,FALSE),"") | D5: =IFERROR(IF(VLOOKUP($A5,'Parts List and Volumes'!$C4:$F266,3,FALSE)=0,"",VLOOKUP(A5,'Parts List and Volumes'!C4:F266,3,FALSE)),"") | E5: =IFERROR(IF(VLOOKUP($A5,'Parts List and Volumes'!$C4:$F266,4,FALSE)=0,"",VLOOKUP(B5,'Parts List and Volumes'!D4:G266,3,FALSE)),"") | G5: =IFERROR(VLOOKUP($A5,'Parts List and Volumes'!$C$2:$W196,5,FALSE),"") | H5: =IFERROR(VLOOKUP($A5,'Parts List and Volumes'!$C$2:$W196,6,FALSE),"") | I5: =IFERROR((($F5*G5)/FourHeadAssumption),"") | J5: =IFERROR((($F5*H5)/FourHeadAssumption),"") | K5: =IFERROR(VLOOKUP($A5,'Parts List and Volumes'!$C$2:$W196,7,FALSE),"") | L5: =IFERROR(VLOOKUP($A5,'Parts List and Volumes'!$C$2:$W196,8,FALSE),"") | M5: =IFERROR((($F5*K5)/FourHeadAssumption),"") | N5: =IFERROR((($F5*L5)/FourHeadAssumption),"") | O5: =IFERROR(VLOOKUP($A5,'Parts List and Volumes'!$C$2:$W196,9,FALSE),"") | P5: =IFERROR(VLOOKUP($A5,'Parts List and Volumes'!$C$2:$W196,10,FALSE),"") | Q5: =IFERROR((($F5*O5)/FourHeadAssumption),"") | R5: =IFERROR((($F5*P5)/FourHeadAssumption),"") | S5: =IFERROR(VLOOKUP($A5,'Parts List and Volumes'!$C$2:$W196,11,FALSE),"") | T5: =IFERROR(VLOOKUP($A5,'Parts List and Volumes'!$C$2:$W196,12,FALSE),"") | U5: =IFERROR((($F5*S5)/FourHeadAssumption),"") | V5: =IFERROR((($F5*T5)/FourHeadAssumption),"") | W5: =IFERROR(VLOOKUP($A5,'Parts List and Volumes'!$C$2:$W196,13,FALSE),"") | X5: =IFERROR(VLOOKUP($A5,'Parts List and Volumes'!$C$2:$W196,14,FALSE),"") | Y5: =IFERROR((($F5*W5)/FourHeadAssumption),"") | Z5: =IFERROR((($F5*X5)/FourHeadAssumption),"") | AA5: =IFERROR(VLOOKUP($A5,'Parts List and Volumes'!$C$2:$W196,15,FALSE),"") | AB5: =IFERROR(VLOOKUP($A5,'Parts List and Volumes'!$C$2:$W196,16,FALSE),"") | AC5: =IFERROR((($F5*AA5)/FourHeadAssumption),"") | AD5: =IFERROR((($F5*AB5)/FourHeadAssumption),"") | AE5: =IFERROR(VLOOKUP($A5,'Parts List and Volumes'!$C$2:$W196,17,FALSE),"") | AF5: =IFERROR(VLOOKUP($A5,'Parts List and Volumes'!$C$2:$W196,18,FALSE),"") | AG5: =IFERROR((($F5*AE5)/FourHeadAssumption),"") | AH5: =IFERROR((($F5*AF5)/FourHeadAssumption),"") | AI5: =IFERROR(VLOOKUP($A5,'Parts List and Volumes'!$C$2:$W196,19,FALSE),"") | AJ5: =IFERROR(VLOOKUP($A5,'Parts List and Volumes'!$C$2:$W196,20,FALSE),"") | AK5: =IFERROR((($F5*AI5)/FourHeadAssumption),"") | AL5: =IFERROR((($F5*AJ5)/FourHeadAssumption),"") | AM5: =IFERROR(VLOOKUP($A5,'Parts List and Volumes'!$C$2:$W196,21,FALSE),"") | AN5: =IFERROR(VLOOKUP($A5,'Parts List and Volumes'!$C$2:$W196,22,FALSE),"") | AO5: =IFERROR((($F5*AM5)/FourHeadAssumption),"") | AP5: =IFERROR((($F5*AN5)/FourHeadAssumption),"") | AQ5: =IFERROR(VLOOKUP($A5,'Parts List and Volumes'!$C$2:$W196,23,FALSE),"") | AR5: =IFERROR(VLOOKUP($A5,'Parts List and Volumes'!$C$2:$W196,24,FALSE),"") | AS5: =IFERROR((($F5*AQ5)/FourHeadAssumption),"") | AT5: =IFERROR((($F5*AR5)/FourHeadAssumption),"") | AU5: =IFERROR(VLOOKUP($A5,'Parts List and Volumes'!$C$2:$W196,25,FALSE),"") | AV5: =IFERROR(VLOOKUP($A5,'Parts List and Volumes'!$C$2:$W196,26,FALSE),"") | AW5: =IFERROR((($F5*AU5)/FourHeadAssumption),"") | AX5: =IFERROR((($F5*AV5)/FourHeadAssumption),"")
C6: =IFERROR(VLOOKUP(A6,'Parts List and Volumes'!C5:D197,2,FALSE),"") | D6: =IFERROR(IF(VLOOKUP($A6,'Parts List and Volumes'!$C5:$F266,3,FALSE)=0,"",VLOOKUP(A6,'Parts List and Volumes'!C5:F266,3,FALSE)),"") | E6: =IFERROR(IF(VLOOKUP($A6,'Parts List and Volumes'!$C5:$F266,4,FALSE)=0,"",VLOOKUP(B6,'Parts List and Volumes'!D5:G266,3,FALSE)),"") | G6: =IFERROR(VLOOKUP($A6,'Parts List and Volumes'!$C$2:$W197,5,FALSE),"") | H6: =IFERROR(VLOOKUP($A6,'Parts List and Volumes'!$C$2:$W197,6,FALSE),"") | I6: =IFERROR((($F6*G6)/FourHeadAssumption),"") | J6: =IFERROR((($F6*H6)/FourHeadAssumption),"") | K6: =IFERROR(VLOOKUP($A6,'Parts List and Volumes'!$C$2:$W197,7,FALSE),"") | L6: =IFERROR(VLOOKUP($A6,'Parts List and Volumes'!$C$2:$W197,8,FALSE),"") | M6: =IFERROR((($F6*K6)/FourHeadAssumption),"") | N6: =IFERROR((($F6*L6)/FourHeadAssumption),"") | O6: =IFERROR(VLOOKUP($A6,'Parts List and Volumes'!$C$2:$W197,9,FALSE),"") | P6: =IFERROR(VLOOKUP($A6,'Parts List and Volumes'!$C$2:$W197,10,FALSE),"") | Q6: =IFERROR((($F6*O6)/FourHeadAssumption),"") | R6: =IFERROR((($F6*P6)/FourHeadAssumption),"") | S6: =IFERROR(VLOOKUP($A6,'Parts List and Volumes'!$C$2:$W197,11,FALSE),"") | T6: =IFERROR(VLOOKUP($A6,'Parts List and Volumes'!$C$2:$W197,12,FALSE),"") | U6: =IFERROR((($F6*S6)/FourHeadAssumption),"") | V6: =IFERROR((($F6*T6)/FourHeadAssumption),"") | W6: =IFERROR(VLOOKUP($A6,'Parts List and Volumes'!$C$2:$W197,13,FALSE),"") | X6: =IFERROR(VLOOKUP($A6,'Parts List and Volumes'!$C$2:$W197,14,FALSE),"") | Y6: =IFERROR((($F6*W6)/FourHeadAssumption),"") | Z6: =IFERROR((($F6*X6)/FourHeadAssumption),"") | AA6: =IFERROR(VLOOKUP($A6,'Parts List and Volumes'!$C$2:$W197,15,FALSE),"") | AB6: =IFERROR(VLOOKUP($A6,'Parts List and Volumes'!$C$2:$W197,16,FALSE),"") | AC6: =IFERROR((($F6*AA6)/FourHeadAssumption),"") | AD6: =IFERROR((($F6*AB6)/FourHeadAssumption),"") | AE6: =IFERROR(VLOOKUP($A6,'Parts List and Volumes'!$C$2:$W197,17,FALSE),"") | AF6: =IFERROR(VLOOKUP($A6,'Parts List and Volumes'!$C$2:$W197,18,FALSE),"") | AG6: =IFERROR((($F6*AE6)/FourHeadAssumption),"") | AH6: =IFERROR((($F6*AF6)/FourHeadAssumption),"") | AI6: =IFERROR(VLOOKUP($A6,'Parts List and Volumes'!$C$2:$W197,19,FALSE),"") | AJ6: =IFERROR(VLOOKUP($A6,'Parts List and Volumes'!$C$2:$W197,20,FALSE),"") | AK6: =IFERROR((($F6*AI6)/FourHeadAssumption),"") | AL6: =IFERROR((($F6*AJ6)/FourHeadAssumption),"") | AM6: =IFERROR(VLOOKUP($A6,'Parts List and Volumes'!$C$2:$W197,21,FALSE),"") | AN6: =IFERROR(VLOOKUP($A6,'Parts List and Volumes'!$C$2:$W197,22,FALSE),"") | AO6: =IFERROR((($F6*AM6)/FourHeadAssumption),"") | AP6: =IFERROR((($F6*AN6)/FourHeadAssumption),"") | AQ6: =IFERROR(VLOOKUP($A6,'Parts List and Volumes'!$C$2:$W197,23,FALSE),"") | AR6: =IFERROR(VLOOKUP($A6,'Parts List and Volumes'!$C$2:$W197,24,FALSE),"") | AS6: =IFERROR((($F6*AQ6)/FourHeadAssumption),"") | AT6: =IFERROR((($F6*AR6)/FourHeadAssumption),"") | AU6: =IFERROR(VLOOKUP($A6,'Parts List and Volumes'!$C$2:$W197,25,FALSE),"") | AV6: =IFERROR(VLOOKUP($A6,'Parts List and Volumes'!$C$2:$W197,26,FALSE),"") | AW6: =IFERROR((($F6*AU6)/FourHeadAssumption),"") | AX6: =IFERROR((($F6*AV6)/FourHeadAssumption),"")
C7: =IFERROR(VLOOKUP(A7,'Parts List and Volumes'!C6:D198,2,FALSE),"") | D7: =IFERROR(IF(VLOOKUP($A7,'Parts List and Volumes'!$C6:$F266,3,FALSE)=0,"",VLOOKUP(A7,'Parts List and Volumes'!C6:F266,3,FALSE)),"") | E7: =IFERROR(IF(VLOOKUP($A7,'Parts List and Volumes'!$C6:$F266,4,FALSE)=0,"",VLOOKUP(B7,'Parts List and Volumes'!D6:G266,3,FALSE)),"") | G7: =IFERROR(VLOOKUP($A7,'Parts List and Volumes'!$C$2:$W198,5,FALSE),"") | H7: =IFERROR(VLOOKUP($A7,'Parts List and Volumes'!$C$2:$W198,6,FALSE),"") | I7: =IFERROR((($F7*G7)/FourHeadAssumption),"") | J7: =IFERROR((($F7*H7)/FourHeadAssumption),"") | K7: =IFERROR(VLOOKUP($A7,'Parts List and Volumes'!$C$2:$W198,7,FALSE),"") | L7: =IFERROR(VLOOKUP($A7,'Parts List and Volumes'!$C$2:$W198,8,FALSE),"") | M7: =IFERROR((($F7*K7)/FourHeadAssumption),"") | N7: =IFERROR((($F7*L7)/FourHeadAssumption),"") | O7: =IFERROR(VLOOKUP($A7,'Parts List and Volumes'!$C$2:$W198,9,FALSE),"") | P7: =IFERROR(VLOOKUP($A7,'Parts List and Volumes'!$C$2:$W198,10,FALSE),"") | Q7: =IFERROR((($F7*O7)/FourHeadAssumption),"") | R7: =IFERROR((($F7*P7)/FourHeadAssumption),"") | S7: =IFERROR(VLOOKUP($A7,'Parts List and Volumes'!$C$2:$W198,11,FALSE),"") | T7: =IFERROR(VLOOKUP($A7,'Parts List and Volumes'!$C$2:$W198,12,FALSE),"") | U7: =IFERROR((($F7*S7)/FourHeadAssumption),"") | V7: =IFERROR((($F7*T7)/FourHeadAssumption),"") | W7: =IFERROR(VLOOKUP($A7,'Parts List and Volumes'!$C$2:$W198,13,FALSE),"") | X7: =IFERROR(VLOOKUP($A7,'Parts List and Volumes'!$C$2:$W198,14,FALSE),"") | Y7: =IFERROR((($F7*W7)/FourHeadAssumption),"") | Z7: =IFERROR((($F7*X7)/FourHeadAssumption),"") | AA7: =IFERROR(VLOOKUP($A7,'Parts List and Volumes'!$C$2:$W198,15,FALSE),"") | AB7: =IFERROR(VLOOKUP($A7,'Parts List and Volumes'!$C$2:$W198,16,FALSE),"") | AC7: =IFERROR((($F7*AA7)/FourHeadAssumption),"") | AD7: =IFERROR((($F7*AB7)/FourHeadAssumption),"") | AE7: =IFERROR(VLOOKUP($A7,'Parts List and Volumes'!$C$2:$W198,17,FALSE),"") | AF7: =IFERROR(VLOOKUP($A7,'Parts List and Volumes'!$C$2:$W198,18,FALSE),"") | AG7: =IFERROR((($F7*AE7)/FourHeadAssumption),"") | AH7: =IFERROR((($F7*AF7)/FourHeadAssumption),"") | AI7: =IFERROR(VLOOKUP($A7,'Parts List and Volumes'!$C$2:$W198,19,FALSE),"") | AJ7: =IFERROR(VLOOKUP($A7,'Parts List and Volumes'!$C$2:$W198,20,FALSE),"") | AK7: =IFERROR((($F7*AI7)/FourHeadAssumption),"") | AL7: =IFERROR((($F7*AJ7)/FourHeadAssumption),"") | AM7: =IFERROR(VLOOKUP($A7,'Parts List and Volumes'!$C$2:$W198,21,FALSE),"") | AN7: =IFERROR(VLOOKUP($A7,'Parts List and Volumes'!$C$2:$W198,22,FALSE),"") | AO7: =IFERROR((($F7*AM7)/FourHeadAssumption),"") | AP7: =IFERROR((($F7*AN7)/FourHeadAssumption),"") | AQ7: =IFERROR(VLOOKUP($A7,'Parts List and Volumes'!$C$2:$W198,23,FALSE),"") | AR7: =IFERROR(VLOOKUP($A7,'Parts List and Volumes'!$C$2:$W198,24,FALSE),"") | AS7: =IFERROR((($F7*AQ7)/FourHeadAssumption),"") | AT7: =IFERROR((($F7*AR7)/FourHeadAssumption),"") | AU7: =IFERROR(VLOOKUP($A7,'Parts List and Volumes'!$C$2:$W198,25,FALSE),"") | AV7: =IFERROR(VLOOKUP($A7,'Parts List and Volumes'!$C$2:$W198,26,FALSE),"") | AW7: =IFERROR((($F7*AU7)/FourHeadAssumption),"") | AX7: =IFERROR((($F7*AV7)/FourHeadAssumption),"")
C8: =IFERROR(VLOOKUP(A8,'Parts List and Volumes'!C7:D199,2,FALSE),"") | D8: =IFERROR(IF(VLOOKUP($A8,'Parts List and Volumes'!$C7:$F266,3,FALSE)=0,"",VLOOKUP(A8,'Parts List and Volumes'!C7:F266,3,FALSE)),"") | E8: =IFERROR(IF(VLOOKUP($A8,'Parts List and Volumes'!$C7:$F266,4,FALSE)=0,"",VLOOKUP(B8,'Parts List and Volumes'!D7:G266,3,FALSE)),"") | G8: =IFERROR(VLOOKUP($A8,'Parts List and Volumes'!$C$2:$W199,5,FALSE),"") | H8: =IFERROR(VLOOKUP($A8,'Parts List and Volumes'!$C$2:$W199,6,FALSE),"") | I8: =IFERROR((($F8*G8)/FourHeadAssumption),"") | J8: =IFERROR((($F8*H8)/FourHeadAssumption),"") | K8: =IFERROR(VLOOKUP($A8,'Parts List and Volumes'!$C$2:$W199,7,FALSE),"") | L8: =IFERROR(VLOOKUP($A8,'Parts List and Volumes'!$C$2:$W199,8,FALSE),"") | M8: =IFERROR((($F8*K8)/FourHeadAssumption),"") | N8: =IFERROR((($F8*L8)/FourHeadAssumption),"") | O8: =IFERROR(VLOOKUP($A8,'Parts List and Volumes'!$C$2:$W199,9,FALSE),"") | P8: =IFERROR(VLOOKUP($A8,'Parts List and Volumes'!$C$2:$W199,10,FALSE),"") | Q8: =IFERROR((($F8*O8)/FourHeadAssumption),"") | R8: =IFERROR((($F8*P8)/FourHeadAssumption),"") | S8: =IFERROR(VLOOKUP($A8,'Parts List and Volumes'!$C$2:$W199,11,FALSE),"") | T8: =IFERROR(VLOOKUP($A8,'Parts List and Volumes'!$C$2:$W199,12,FALSE),"") | U8: =IFERROR((($F8*S8)/FourHeadAssumption),"") | V8: =IFERROR((($F8*T8)/FourHeadAssumption),"") | W8: =IFERROR(VLOOKUP($A8,'Parts List and Volumes'!$C$2:$W199,13,FALSE),"") | X8: =IFERROR(VLOOKUP($A8,'Parts List and Volumes'!$C$2:$W199,14,FALSE),"") | Y8: =IFERROR((($F8*W8)/FourHeadAssumption),"") | Z8: =IFERROR((($F8*X8)/FourHeadAssumption),"") | AA8: =IFERROR(VLOOKUP($A8,'Parts List and Volumes'!$C$2:$W199,15,FALSE),"") | AB8: =IFERROR(VLOOKUP($A8,'Parts List and Volumes'!$C$2:$W199,16,FALSE),"") | AC8: =IFERROR((($F8*AA8)/FourHeadAssumption),"") | AD8: =IFERROR((($F8*AB8)/FourHeadAssumption),"") | AE8: =IFERROR(VLOOKUP($A8,'Parts List and Volumes'!$C$2:$W199,17,FALSE),"") | AF8: =IFERROR(VLOOKUP($A8,'Parts List and Volumes'!$C$2:$W199,18,FALSE),"") | AG8: =IFERROR((($F8*AE8)/FourHeadAssumption),"") | AH8: =IFERROR((($F8*AF8)/FourHeadAssumption),"") | AI8: =IFERROR(VLOOKUP($A8,'Parts List and Volumes'!$C$2:$W199,19,FALSE),"") | AJ8: =IFERROR(VLOOKUP($A8,'Parts List and Volumes'!$C$2:$W199,20,FALSE),"") | AK8: =IFERROR((($F8*AI8)/FourHeadAssumption),"") | AL8: =IFERROR((($F8*AJ8)/FourHeadAssumption),"") | AM8: =IFERROR(VLOOKUP($A8,'Parts List and Volumes'!$C$2:$W199,21,FALSE),"") | AN8: =IFERROR(VLOOKUP($A8,'Parts List and Volumes'!$C$2:$W199,22,FALSE),"") | AO8: =IFERROR((($F8*AM8)/FourHeadAssumption),"") | AP8: =IFERROR((($F8*AN8)/FourHeadAssumption),"") | AQ8: =IFERROR(VLOOKUP($A8,'Parts List and Volumes'!$C$2:$W199,23,FALSE),"") | AR8: =IFERROR(VLOOKUP($A8,'Parts List and Volumes'!$C$2:$W199,24,FALSE),"") | AS8: =IFERROR((($F8*AQ8)/FourHeadAssumption),"") | AT8: =IFERROR((($F8*AR8)/FourHeadAssumption),"") | AU8: =IFERROR(VLOOKUP($A8,'Parts List and Volumes'!$C$2:$W199,25,FALSE),"") | AV8: =IFERROR(VLOOKUP($A8,'Parts List and Volumes'!$C$2:$W199,26,FALSE),"") | AW8: =IFERROR((($F8*AU8)/FourHeadAssumption),"") | AX8: =IFERROR((($F8*AV8)/FourHeadAssumption),"")
C9: =IFERROR(VLOOKUP(A9,'Parts List and Volumes'!C8:D200,2,FALSE),"") | D9: =IFERROR(IF(VLOOKUP($A9,'Parts List and Volumes'!$C8:$F266,3,FALSE)=0,"",VLOOKUP(A9,'Parts List and Volumes'!C8:F266,3,FALSE)),"") | E9: =IFERROR(IF(VLOOKUP($A9,'Parts List and Volumes'!$C8:$F266,4,FALSE)=0,"",VLOOKUP(B9,'Parts List and Volumes'!D8:G266,3,FALSE)),"") | G9: =IFERROR(VLOOKUP($A9,'Parts List and Volumes'!$C$2:$W200,5,FALSE),"") | H9: =IFERROR(VLOOKUP($A9,'Parts List and Volumes'!$C$2:$W200,6,FALSE),"") | I9: =IFERROR((($F9*G9)/FourHeadAssumption),"") | J9: =IFERROR((($F9*H9)/FourHeadAssumption),"") | K9: =IFERROR(VLOOKUP($A9,'Parts List and Volumes'!$C$2:$W200,7,FALSE),"") | L9: =IFERROR(VLOOKUP($A9,'Parts List and Volumes'!$C$2:$W200,8,FALSE),"") | M9: =IFERROR((($F9*K9)/FourHeadAssumption),"") | N9: =IFERROR((($F9*L9)/FourHeadAssumption),"") | O9: =IFERROR(VLOOKUP($A9,'Parts List and Volumes'!$C$2:$W200,9,FALSE),"") | P9: =IFERROR(VLOOKUP($A9,'Parts List and Volumes'!$C$2:$W200,10,FALSE),"") | Q9: =IFERROR((($F9*O9)/FourHeadAssumption),"") | R9: =IFERROR((($F9*P9)/FourHeadAssumption),"") | S9: =IFERROR(VLOOKUP($A9,'Parts List and Volumes'!$C$2:$W200,11,FALSE),"") | T9: =IFERROR(VLOOKUP($A9,'Parts List and Volumes'!$C$2:$W200,12,FALSE),"") | U9: =IFERROR((($F9*S9)/FourHeadAssumption),"") | V9: =IFERROR((($F9*T9)/FourHeadAssumption),"") | W9: =IFERROR(VLOOKUP($A9,'Parts List and Volumes'!$C$2:$W200,13,FALSE),"") | X9: =IFERROR(VLOOKUP($A9,'Parts List and Volumes'!$C$2:$W200,14,FALSE),"") | Y9: =IFERROR((($F9*W9)/FourHeadAssumption),"") | Z9: =IFERROR((($F9*X9)/FourHeadAssumption),"") | AA9: =IFERROR(VLOOKUP($A9,'Parts List and Volumes'!$C$2:$W200,15,FALSE),"") | AB9: =IFERROR(VLOOKUP($A9,'Parts List and Volumes'!$C$2:$W200,16,FALSE),"") | AC9: =IFERROR((($F9*AA9)/FourHeadAssumption),"") | AD9: =IFERROR((($F9*AB9)/FourHeadAssumption),"") | AE9: =IFERROR(VLOOKUP($A9,'Parts List and Volumes'!$C$2:$W200,17,FALSE),"") | AF9: =IFERROR(VLOOKUP($A9,'Parts List and Volumes'!$C$2:$W200,18,FALSE),"") | AG9: =IFERROR((($F9*AE9)/FourHeadAssumption),"") | AH9: =IFERROR((($F9*AF9)/FourHeadAssumption),"") | AI9: =IFERROR(VLOOKUP($A9,'Parts List and Volumes'!$C$2:$W200,19,FALSE),"") | AJ9: =IFERROR(VLOOKUP($A9,'Parts List and Volumes'!$C$2:$W200,20,FALSE),"") | AK9: =IFERROR((($F9*AI9)/FourHeadAssumption),"") | AL9: =IFERROR((($F9*AJ9)/FourHeadAssumption),"") | AM9: =IFERROR(VLOOKUP($A9,'Parts List and Volumes'!$C$2:$W200,21,FALSE),"") | AN9: =IFERROR(VLOOKUP($A9,'Parts List and Volumes'!$C$2:$W200,22,FALSE),"") | AO9: =IFERROR((($F9*AM9)/FourHeadAssumption),"") | AP9: =IFERROR((($F9*AN9)/FourHeadAssumption),"") | AQ9: =IFERROR(VLOOKUP($A9,'Parts List and Volumes'!$C$2:$W200,23,FALSE),"") | AR9: =IFERROR(VLOOKUP($A9,'Parts List and Volumes'!$C$2:$W200,24,FALSE),"") | AS9: =IFERROR((($F9*AQ9)/FourHeadAssumption),"") | AT9: =IFERROR((($F9*AR9)/FourHeadAssumption),"") | AU9: =IFERROR(VLOOKUP($A9,'Parts List and Volumes'!$C$2:$W200,25,FALSE),"") | AV9: =IFERROR(VLOOKUP($A9,'Parts List and Volumes'!$C$2:$W200,26,FALSE),"") | AW9: =IFERROR((($F9*AU9)/FourHeadAssumption),"") | AX9: =IFERROR((($F9*AV9)/FourHeadAssumption),"")
C10: =IFERROR(VLOOKUP(A10,'Parts List and Volumes'!C9:D201,2,FALSE),"") | D10: =IFERROR(IF(VLOOKUP($A10,'Parts List and Volumes'!$C9:$F266,3,FALSE)=0,"",VLOOKUP(A10,'Parts List and Volumes'!C9:F266,3,FALSE)),"") | E10: =IFERROR(IF(VLOOKUP($A10,'Parts List and Volumes'!$C9:$F266,4,FALSE)=0,"",VLOOKUP(B10,'Parts List and Volumes'!D9:G266,3,FALSE)),"") | G10: =IFERROR(VLOOKUP($A10,'Parts List and Volumes'!$C$2:$W201,5,FALSE),"") | H10: =IFERROR(VLOOKUP($A10,'Parts List and Volumes'!$C$2:$W201,6,FALSE),"") | I10: =IFERROR((($F10*G10)/FourHeadAssumption),"") | J10: =IFERROR((($F10*H10)/FourHeadAssumption),"") | K10: =IFERROR(VLOOKUP($A10,'Parts List and Volumes'!$C$2:$W201,7,FALSE),"") | L10: =IFERROR(VLOOKUP($A10,'Parts List and Volumes'!$C$2:$W201,8,FALSE),"") | M10: =IFERROR((($F10*K10)/FourHeadAssumption),"") | N10: =IFERROR((($F10*L10)/FourHeadAssumption),"") | O10: =IFERROR(VLOOKUP($A10,'Parts List and Volumes'!$C$2:$W201,9,FALSE),"") | P10: =IFERROR(VLOOKUP($A10,'Parts List and Volumes'!$C$2:$W201,10,FALSE),"") | Q10: =IFERROR((($F10*O10)/FourHeadAssumption),"") | R10: =IFERROR((($F10*P10)/FourHeadAssumption),"") | S10: =IFERROR(VLOOKUP($A10,'Parts List and Volumes'!$C$2:$W201,11,FALSE),"") | T10: =IFERROR(VLOOKUP($A10,'Parts List and Volumes'!$C$2:$W201,12,FALSE),"") | U10: =IFERROR((($F10*S10)/FourHeadAssumption),"") | V10: =IFERROR((($F10*T10)/FourHeadAssumption),"") | W10: =IFERROR(VLOOKUP($A10,'Parts List and Volumes'!$C$2:$W201,13,FALSE),"") | X10: =IFERROR(VLOOKUP($A10,'Parts List and Volumes'!$C$2:$W201,14,FALSE),"") | Y10: =IFERROR((($F10*W10)/FourHeadAssumption),"") | Z10: =IFERROR((($F10*X10)/FourHeadAssumption),"") | AA10: =IFERROR(VLOOKUP($A10,'Parts List and Volumes'!$C$2:$W201,15,FALSE),"") | AB10: =IFERROR(VLOOKUP($A10,'Parts List and Volumes'!$C$2:$W201,16,FALSE),"") | AC10: =IFERROR((($F10*AA10)/FourHeadAssumption),"") | AD10: =IFERROR((($F10*AB10)/FourHeadAssumption),"") | AE10: =IFERROR(VLOOKUP($A10,'Parts List and Volumes'!$C$2:$W201,17,FALSE),"") | AF10: =IFERROR(VLOOKUP($A10,'Parts List and Volumes'!$C$2:$W201,18,FALSE),"") | AG10: =IFERROR((($F10*AE10)/FourHeadAssumption),"") | AH10: =IFERROR((($F10*AF10)/FourHeadAssumption),"") | AI10: =IFERROR(VLOOKUP($A10,'Parts List and Volumes'!$C$2:$W201,19,FALSE),"") | AJ10: =IFERROR(VLOOKUP($A10,'Parts List and Volumes'!$C$2:$W201,20,FALSE),"") | AK10: =IFERROR((($F10*AI10)/FourHeadAssumption),"") | AL10: =IFERROR((($F10*AJ10)/FourHeadAssumption),"") | AM10: =IFERROR(VLOOKUP($A10,'Parts List and Volumes'!$C$2:$W201,21,FALSE),"") | AN10: =IFERROR(VLOOKUP($A10,'Parts List and Volumes'!$C$2:$W201,22,FALSE),"") | AO10: =IFERROR((($F10*AM10)/FourHeadAssumption),"") | AP10: =IFERROR((($F10*AN10)/FourHeadAssumption),"") | AQ10: =IFERROR(VLOOKUP($A10,'Parts List and Volumes'!$C$2:$W201,23,FALSE),"") | AR10: =IFERROR(VLOOKUP($A10,'Parts List and Volumes'!$C$2:$W201,24,FALSE),"") | AS10: =IFERROR((($F10*AQ10)/FourHeadAssumption),"") | AT10: =IFERROR((($F10*AR10)/FourHeadAssumption),"") | AU10: =IFERROR(VLOOKUP($A10,'Parts List and Volumes'!$C$2:$W201,25,FALSE),"") | AV10: =IFERROR(VLOOKUP($A10,'Parts List and Volumes'!$C$2:$W201,26,FALSE),"") | AW10: =IFERROR((($F10*AU10)/FourHeadAssumption),"") | AX10: =IFERROR((($F10*AV10)/FourHeadAssumption),"")
C11: =IFERROR(VLOOKUP(A11,'Parts List and Volumes'!C10:D202,2,FALSE),"") | D11: =IFERROR(IF(VLOOKUP($A11,'Parts List and Volumes'!$C10:$F266,3,FALSE)=0,"",VLOOKUP(A11,'Parts List and Volumes'!C10:F266,3,FALSE)),"") | E11: =IFERROR(IF(VLOOKUP($A11,'Parts List and Volumes'!$C10:$F266,4,FALSE)=0,"",VLOOKUP(B11,'Parts List and Volumes'!D10:G266,3,FALSE)),"") | G11: =IFERROR(VLOOKUP($A11,'Parts List and Volumes'!$C$2:$W202,5,FALSE),"") | H11: =IFERROR(VLOOKUP($A11,'Parts List and Volumes'!$C$2:$W202,6,FALSE),"") | I11: =IFERROR((($F11*G11)/FourHeadAssumption),"") | J11: =IFERROR((($F11*H11)/FourHeadAssumption),"") | K11: =IFERROR(VLOOKUP($A11,'Parts List and Volumes'!$C$2:$W202,7,FALSE),"") | L11: =IFERROR(VLOOKUP($A11,'Parts List and Volumes'!$C$2:$W202,8,FALSE),"") | M11: =IFERROR((($F11*K11)/FourHeadAssumption),"") | N11: =IFERROR((($F11*L11)/FourHeadAssumption),"") | O11: =IFERROR(VLOOKUP($A11,'Parts List and Volumes'!$C$2:$W202,9,FALSE),"") | P11: =IFERROR(VLOOKUP($A11,'Parts List and Volumes'!$C$2:$W202,10,FALSE),"") | Q11: =IFERROR((($F11*O11)/FourHeadAssumption),"") | R11: =IFERROR((($F11*P11)/FourHeadAssumption),"") | S11: =IFERROR(VLOOKUP($A11,'Parts List and Volumes'!$C$2:$W202,11,FALSE),"") | T11: =IFERROR(VLOOKUP($A11,'Parts List and Volumes'!$C$2:$W202,12,FALSE),"") | U11: =IFERROR((($F11*S11)/FourHeadAssumption),"") | V11: =IFERROR((($F11*T11)/FourHeadAssumption),"") | W11: =IFERROR(VLOOKUP($A11,'Parts List and Volumes'!$C$2:$W202,13,FALSE),"") | X11: =IFERROR(VLOOKUP($A11,'Parts List and Volumes'!$C$2:$W202,14,FALSE),"") | Y11: =IFERROR((($F11*W11)/FourHeadAssumption),"") | Z11: =IFERROR((($F11*X11)/FourHeadAssumption),"") | AA11: =IFERROR(VLOOKUP($A11,'Parts List and Volumes'!$C$2:$W202,15,FALSE),"") | AB11: =IFERROR(VLOOKUP($A11,'Parts List and Volumes'!$C$2:$W202,16,FALSE),"") | AC11: =IFERROR((($F11*AA11)/FourHeadAssumption),"") | AD11: =IFERROR((($F11*AB11)/FourHeadAssumption),"") | AE11: =IFERROR(VLOOKUP($A11,'Parts List and Volumes'!$C$2:$W202,17,FALSE),"") | AF11: =IFERROR(VLOOKUP($A11,'Parts List and Volumes'!$C$2:$W202,18,FALSE),"") | AG11: =IFERROR((($F11*AE11)/FourHeadAssumption),"") | AH11: =IFERROR((($F11*AF11)/FourHeadAssumption),"") | AI11: =IFERROR(VLOOKUP($A11,'Parts List and Volumes'!$C$2:$W202,19,FALSE),"") | AJ11: =IFERROR(VLOOKUP($A11,'Parts List and Volumes'!$C$2:$W202,20,FALSE),"") | AK11: =IFERROR((($F11*AI11)/FourHeadAssumption),"") | AL11: =IFERROR((($F11*AJ11)/FourHeadAssumption),"") | AM11: =IFERROR(VLOOKUP($A11,'Parts List and Volumes'!$C$2:$W202,21,FALSE),"") | AN11: =IFERROR(VLOOKUP($A11,'Parts List and Volumes'!$C$2:$W202,22,FALSE),"") | AO11: =IFERROR((($F11*AM11)/FourHeadAssumption),"") | AP11: =IFERROR((($F11*AN11)/FourHeadAssumption),"") | AQ11: =IFERROR(VLOOKUP($A11,'Parts List and Volumes'!$C$2:$W202,23,FALSE),"") | AR11: =IFERROR(VLOOKUP($A11,'Parts List and Volumes'!$C$2:$W202,24,FALSE),"") | AS11: =IFERROR((($F11*AQ11)/FourHeadAssumption),"") | AT11: =IFERROR((($F11*AR11)/FourHeadAssumption),"") | AU11: =IFERROR(VLOOKUP($A11,'Parts List and Volumes'!$C$2:$W202,25,FALSE),"") | AV11: =IFERROR(VLOOKUP($A11,'Parts List and Volumes'!$C$2:$W202,26,FALSE),"") | AW11: =IFERROR((($F11*AU11)/FourHeadAssumption),"") | AX11: =IFERROR((($F11*AV11)/FourHeadAssumption),"")
C12: =IFERROR(VLOOKUP(A12,'Parts List and Volumes'!C11:D203,2,FALSE),"") | D12: =IFERROR(IF(VLOOKUP($A12,'Parts List and Volumes'!$C11:$F266,3,FALSE)=0,"",VLOOKUP(A12,'Parts List and Volumes'!C11:F266,3,FALSE)),"") | E12: =IFERROR(IF(VLOOKUP($A12,'Parts List and Volumes'!$C11:$F266,4,FALSE)=0,"",VLOOKUP(B12,'Parts List and Volumes'!D11:G266,3,FALSE)),"") | G12: =IFERROR(VLOOKUP($A12,'Parts List and Volumes'!$C$2:$W203,5,FALSE),"") | H12: =IFERROR(VLOOKUP($A12,'Parts List and Volumes'!$C$2:$W203,6,FALSE),"") | I12: =IFERROR((($F12*G12)/FourHeadAssumption),"") | J12: =IFERROR((($F12*H12)/FourHeadAssumption),"") | K12: =IFERROR(VLOOKUP($A12,'Parts List and Volumes'!$C$2:$W203,7,FALSE),"") | L12: =IFERROR(VLOOKUP($A12,'Parts List and Volumes'!$C$2:$W203,8,FALSE),"") | M12: =IFERROR((($F12*K12)/FourHeadAssumption),"") | N12: =IFERROR((($F12*L12)/FourHeadAssumption),"") | O12: =IFERROR(VLOOKUP($A12,'Parts List and Volumes'!$C$2:$W203,9,FALSE),"") | P12: =IFERROR(VLOOKUP($A12,'Parts List and Volumes'!$C$2:$W203,10,FALSE),"") | Q12: =IFERROR((($F12*O12)/FourHeadAssumption),"") | R12: =IFERROR((($F12*P12)/FourHeadAssumption),"") | S12: =IFERROR(VLOOKUP($A12,'Parts List and Volumes'!$C$2:$W203,11,FALSE),"") | T12: =IFERROR(VLOOKUP($A12,'Parts List and Volumes'!$C$2:$W203,12,FALSE),"") | U12: =IFERROR((($F12*S12)/FourHeadAssumption),"") | V12: =IFERROR((($F12*T12)/FourHeadAssumption),"") | W12: =IFERROR(VLOOKUP($A12,'Parts List and Volumes'!$C$2:$W203,13,FALSE),"") | X12: =IFERROR(VLOOKUP($A12,'Parts List and Volumes'!$C$2:$W203,14,FALSE),"") | Y12: =IFERROR((($F12*W12)/FourHeadAssumption),"") | Z12: =IFERROR((($F12*X12)/FourHeadAssumption),"") | AA12: =IFERROR(VLOOKUP($A12,'Parts List and Volumes'!$C$2:$W203,15,FALSE),"") | AB12: =IFERROR(VLOOKUP($A12,'Parts List and Volumes'!$C$2:$W203,16,FALSE),"") | AC12: =IFERROR((($F12*AA12)/FourHeadAssumption),"") | AD12: =IFERROR((($F12*AB12)/FourHeadAssumption),"") | AE12: =IFERROR(VLOOKUP($A12,'Parts List and Volumes'!$C$2:$W203,17,FALSE),"") | AF12: =IFERROR(VLOOKUP($A12,'Parts List and Volumes'!$C$2:$W203,18,FALSE),"") | AG12: =IFERROR((($F12*AE12)/FourHeadAssumption),"") | AH12: =IFERROR((($F12*AF12)/FourHeadAssumption),"") | AI12: =IFERROR(VLOOKUP($A12,'Parts List and Volumes'!$C$2:$W203,19,FALSE),"") | AJ12: =IFERROR(VLOOKUP($A12,'Parts List and Volumes'!$C$2:$W203,20,FALSE),"") | AK12: =IFERROR((($F12*AI12)/FourHeadAssumption),"") | AL12: =IFERROR((($F12*AJ12)/FourHeadAssumption),"") | AM12: =IFERROR(VLOOKUP($A12,'Parts List and Volumes'!$C$2:$W203,21,FALSE),"") | AN12: =IFERROR(VLOOKUP($A12,'Parts List and Volumes'!$C$2:$W203,22,FALSE),"") | AO12: =IFERROR((($F12*AM12)/FourHeadAssumption),"") | AP12: =IFERROR((($F12*AN12)/FourHeadAssumption),"") | AQ12: =IFERROR(VLOOKUP($A12,'Parts List and Volumes'!$C$2:$W203,23,FALSE),"") | AR12: =IFERROR(VLOOKUP($A12,'Parts List and Volumes'!$C$2:$W203,24,FALSE),"") | AS12: =IFERROR((($F12*AQ12)/FourHeadAssumption),"") | AT12: =IFERROR((($F12*AR12)/FourHeadAssumption),"") | AU12: =IFERROR(VLOOKUP($A12,'Parts List and Volumes'!$C$2:$W203,25,FALSE),"") | AV12: =IFERROR(VLOOKUP($A12,'Parts List and Volumes'!$C$2:$W203,26,FALSE),"") | AW12: =IFERROR((($F12*AU12)/FourHeadAssumption),"") | AX12: =IFERROR((($F12*AV12)/FourHeadAssumption),"")
C13: =IFERROR(VLOOKUP(A13,'Parts List and Volumes'!C12:D204,2,FALSE),"") | D13: =IFERROR(IF(VLOOKUP($A13,'Parts List and Volumes'!$C12:$F267,3,FALSE)=0,"",VLOOKUP(A13,'Parts List and Volumes'!C12:F267,3,FALSE)),"") | E13: =IFERROR(IF(VLOOKUP($A13,'Parts List and Volumes'!$C12:$F267,4,FALSE)=0,"",VLOOKUP(B13,'Parts List and Volumes'!D12:G267,3,FALSE)),"") | G13: =IFERROR(VLOOKUP($A13,'Parts List and Volumes'!$C$2:$W204,5,FALSE),"") | H13: =IFERROR(VLOOKUP($A13,'Parts List and Volumes'!$C$2:$W204,6,FALSE),"") | I13: =IFERROR((($F13*G13)/FourHeadAssumption),"") | J13: =IFERROR((($F13*H13)/FourHeadAssumption),"") | K13: =IFERROR(VLOOKUP($A13,'Parts List and Volumes'!$C$2:$W204,7,FALSE),"") | L13: =IFERROR(VLOOKUP($A13,'Parts List and Volumes'!$C$2:$W204,8,FALSE),"") | M13: =IFERROR((($F13*K13)/FourHeadAssumption),"") | N13: =IFERROR((($F13*L13)/FourHeadAssumption),"") | O13: =IFERROR(VLOOKUP($A13,'Parts List and Volumes'!$C$2:$W204,9,FALSE),"") | P13: =IFERROR(VLOOKUP($A13,'Parts List and Volumes'!$C$2:$W204,10,FALSE),"") | Q13: =IFERROR((($F13*O13)/FourHeadAssumption),"") | R13: =IFERROR((($F13*P13)/FourHeadAssumption),"") | S13: =IFERROR(VLOOKUP($A13,'Parts List and Volumes'!$C$2:$W204,11,FALSE),"") | T13: =IFERROR(VLOOKUP($A13,'Parts List and Volumes'!$C$2:$W204,12,FALSE),"") | U13: =IFERROR((($F13*S13)/FourHeadAssumption),"") | V13: =IFERROR((($F13*T13)/FourHeadAssumption),"") | W13: =IFERROR(VLOOKUP($A13,'Parts List and Volumes'!$C$2:$W204,13,FALSE),"") | X13: =IFERROR(VLOOKUP($A13,'Parts List and Volumes'!$C$2:$W204,14,FALSE),"") | Y13: =IFERROR((($F13*W13)/FourHeadAssumption),"") | Z13: =IFERROR((($F13*X13)/FourHeadAssumption),"") | AA13: =IFERROR(VLOOKUP($A13,'Parts List and Volumes'!$C$2:$W204,15,FALSE),"") | AB13: =IFERROR(VLOOKUP($A13,'Parts List and Volumes'!$C$2:$W204,16,FALSE),"") | AC13: =IFERROR((($F13*AA13)/FourHeadAssumption),"") | AD13: =IFERROR((($F13*AB13)/FourHeadAssumption),"") | AE13: =IFERROR(VLOOKUP($A13,'Parts List and Volumes'!$C$2:$W204,17,FALSE),"") | AF13: =IFERROR(VLOOKUP($A13,'Parts List and Volumes'!$C$2:$W204,18,FALSE),"") | AG13: =IFERROR((($F13*AE13)/FourHeadAssumption),"") | AH13: =IFERROR((($F13*AF13)/FourHeadAssumption),"") | AI13: =IFERROR(VLOOKUP($A13,'Parts List and Volumes'!$C$2:$W204,19,FALSE),"") | AJ13: =IFERROR(VLOOKUP($A13,'Parts List and Volumes'!$C$2:$W204,20,FALSE),"") | AK13: =IFERROR((($F13*AI13)/FourHeadAssumption),"") | AL13: =IFERROR((($F13*AJ13)/FourHeadAssumption),"") | AM13: =IFERROR(VLOOKUP($A13,'Parts List and Volumes'!$C$2:$W204,21,FALSE),"") | AN13: =IFERROR(VLOOKUP($A13,'Parts List and Volumes'!$C$2:$W204,22,FALSE),"") | AO13: =IFERROR((($F13*AM13)/FourHeadAssumption),"") | AP13: =IFERROR((($F13*AN13)/FourHeadAssumption),"") | AQ13: =IFERROR(VLOOKUP($A13,'Parts List and Volumes'!$C$2:$W204,23,FALSE),"") | AR13: =IFERROR(VLOOKUP($A13,'Parts List and Volumes'!$C$2:$W204,24,FALSE),"") | AS13: =IFERROR((($F13*AQ13)/FourHeadAssumption),"") | AT13: =IFERROR((($F13*AR13)/FourHeadAssumption),"") | AU13: =IFERROR(VLOOKUP($A13,'Parts List and Volumes'!$C$2:$W204,25,FALSE),"") | AV13: =IFERROR(VLOOKUP($A13,'Parts List and Volumes'!$C$2:$W204,26,FALSE),"") | AW13: =IFERROR((($F13*AU13)/FourHeadAssumption),"") | AX13: =IFERROR((($F13*AV13)/FourHeadAssumption),"")
C14: =IFERROR(VLOOKUP(A14,'Parts List and Volumes'!C13:D205,2,FALSE),"") | D14: =IFERROR(IF(VLOOKUP($A14,'Parts List and Volumes'!$C13:$F268,3,FALSE)=0,"",VLOOKUP(A14,'Parts List and Volumes'!C13:F268,3,FALSE)),"") | E14: =IFERROR(IF(VLOOKUP($A14,'Parts List and Volumes'!$C13:$F268,4,FALSE)=0,"",VLOOKUP(B14,'Parts List and Volumes'!D13:G268,3,FALSE)),"") | G14: =IFERROR(VLOOKUP($A14,'Parts List and Volumes'!$C$2:$W205,5,FALSE),"") | H14: =IFERROR(VLOOKUP($A14,'Parts List and Volumes'!$C$2:$W205,6,FALSE),"") | I14: =IFERROR((($F14*G14)/FourHeadAssumption),"") | J14: =IFERROR((($F14*H14)/FourHeadAssumption),"") | K14: =IFERROR(VLOOKUP($A14,'Parts List and Volumes'!$C$2:$W205,7,FALSE),"") | L14: =IFERROR(VLOOKUP($A14,'Parts List and Volumes'!$C$2:$W205,8,FALSE),"") | M14: =IFERROR((($F14*K14)/FourHeadAssumption),"") | N14: =IFERROR((($F14*L14)/FourHeadAssumption),"") | O14: =IFERROR(VLOOKUP($A14,'Parts List and Volumes'!$C$2:$W205,9,FALSE),"") | P14: =IFERROR(VLOOKUP($A14,'Parts List and Volumes'!$C$2:$W205,10,FALSE),"") | Q14: =IFERROR((($F14*O14)/FourHeadAssumption),"") | R14: =IFERROR((($F14*P14)/FourHeadAssumption),"") | S14: =IFERROR(VLOOKUP($A14,'Parts List and Volumes'!$C$2:$W205,11,FALSE),"") | T14: =IFERROR(VLOOKUP($A14,'Parts List and Volumes'!$C$2:$W205,12,FALSE),"") | U14: =IFERROR((($F14*S14)/FourHeadAssumption),"") | V14: =IFERROR((($F14*T14)/FourHeadAssumption),"") | W14: =IFERROR(VLOOKUP($A14,'Parts List and Volumes'!$C$2:$W205,13,FALSE),"") | X14: =IFERROR(VLOOKUP($A14,'Parts List and Volumes'!$C$2:$W205,14,FALSE),"") | Y14: =IFERROR((($F14*W14)/FourHeadAssumption),"") | Z14: =IFERROR((($F14*X14)/FourHeadAssumption),"") | AA14: =IFERROR(VLOOKUP($A14,'Parts List and Volumes'!$C$2:$W205,15,FALSE),"") | AB14: =IFERROR(VLOOKUP($A14,'Parts List and Volumes'!$C$2:$W205,16,FALSE),"") | AC14: =IFERROR((($F14*AA14)/FourHeadAssumption),"") | AD14: =IFERROR((($F14*AB14)/FourHeadAssumption),"") | AE14: =IFERROR(VLOOKUP($A14,'Parts List and Volumes'!$C$2:$W205,17,FALSE),"") | AF14: =IFERROR(VLOOKUP($A14,'Parts List and Volumes'!$C$2:$W205,18,FALSE),"") | AG14: =IFERROR((($F14*AE14)/FourHeadAssumption),"") | AH14: =IFERROR((($F14*AF14)/FourHeadAssumption),"") | AI14: =IFERROR(VLOOKUP($A14,'Parts List and Volumes'!$C$2:$W205,19,FALSE),"") | AJ14: =IFERROR(VLOOKUP($A14,'Parts List and Volumes'!$C$2:$W205,20,FALSE),"") | AK14: =IFERROR((($F14*AI14)/FourHeadAssumption),"") | AL14: =IFERROR((($F14*AJ14)/FourHeadAssumption),"") | AM14: =IFERROR(VLOOKUP($A14,'Parts List and Volumes'!$C$2:$W205,21,FALSE),"") | AN14: =IFERROR(VLOOKUP($A14,'Parts List and Volumes'!$C$2:$W205,22,FALSE),"") | AO14: =IFERROR((($F14*AM14)/FourHeadAssumption),"") | AP14: =IFERROR((($F14*AN14)/FourHeadAssumption),"") | AQ14: =IFERROR(VLOOKUP($A14,'Parts List and Volumes'!$C$2:$W205,23,FALSE),"") | AR14: =IFERROR(VLOOKUP($A14,'Parts List and Volumes'!$C$2:$W205,24,FALSE),"") | AS14: =IFERROR((($F14*AQ14)/FourHeadAssumption),"") | AT14: =IFERROR((($F14*AR14)/FourHeadAssumption),"") | AU14: =IFERROR(VLOOKUP($A14,'Parts List and Volumes'!$C$2:$W205,25,FALSE),"") | AV14: =IFERROR(VLOOKUP($A14,'Parts List and Volumes'!$C$2:$W205,26,FALSE),"") | AW14: =IFERROR((($F14*AU14)/FourHeadAssumption),"") | AX14: =IFERROR((($F14*AV14)/FourHeadAssumption),"")
C15: =IFERROR(VLOOKUP(A15,'Parts List and Volumes'!C14:D206,2,FALSE),"") | D15: =IFERROR(IF(VLOOKUP($A15,'Parts List and Volumes'!$C14:$F269,3,FALSE)=0,"",VLOOKUP(A15,'Parts List and Volumes'!C14:F269,3,FALSE)),"") | E15: =IFERROR(IF(VLOOKUP($A15,'Parts List and Volumes'!$C14:$F269,4,FALSE)=0,"",VLOOKUP(B15,'Parts List and Volumes'!D14:G269,3,FALSE)),"") | G15: =IFERROR(VLOOKUP($A15,'Parts List and Volumes'!$C$2:$W206,5,FALSE),"") | H15: =IFERROR(VLOOKUP($A15,'Parts List and Volumes'!$C$2:$W206,6,FALSE),"") | I15: =IFERROR((($F15*G15)/FourHeadAssumption),"") | J15: =IFERROR((($F15*H15)/FourHeadAssumption),"") | K15: =IFERROR(VLOOKUP($A15,'Parts List and Volumes'!$C$2:$W206,7,FALSE),"") | L15: =IFERROR(VLOOKUP($A15,'Parts List and Volumes'!$C$2:$W206,8,FALSE),"") | M15: =IFERROR((($F15*K15)/FourHeadAssumption),"") | N15: =IFERROR((($F15*L15)/FourHeadAssumption),"") | O15: =IFERROR(VLOOKUP($A15,'Parts List and Volumes'!$C$2:$W206,9,FALSE),"") | P15: =IFERROR(VLOOKUP($A15,'Parts List and Volumes'!$C$2:$W206,10,FALSE),"") | Q15: =IFERROR((($F15*O15)/FourHeadAssumption),"") | R15: =IFERROR((($F15*P15)/FourHeadAssumption),"") | S15: =IFERROR(VLOOKUP($A15,'Parts List and Volumes'!$C$2:$W206,11,FALSE),"") | T15: =IFERROR(VLOOKUP($A15,'Parts List and Volumes'!$C$2:$W206,12,FALSE),"") | U15: =IFERROR((($F15*S15)/FourHeadAssumption),"") | V15: =IFERROR((($F15*T15)/FourHeadAssumption),"") | W15: =IFERROR(VLOOKUP($A15,'Parts List and Volumes'!$C$2:$W206,13,FALSE),"") | X15: =IFERROR(VLOOKUP($A15,'Parts List and Volumes'!$C$2:$W206,14,FALSE),"") | Y15: =IFERROR((($F15*W15)/FourHeadAssumption),"") | Z15: =IFERROR((($F15*X15)/FourHeadAssumption),"") | AA15: =IFERROR(VLOOKUP($A15,'Parts List and Volumes'!$C$2:$W206,15,FALSE),"") | AB15: =IFERROR(VLOOKUP($A15,'Parts List and Volumes'!$C$2:$W206,16,FALSE),"") | AC15: =IFERROR((($F15*AA15)/FourHeadAssumption),"") | AD15: =IFERROR((($F15*AB15)/FourHeadAssumption),"") | AE15: =IFERROR(VLOOKUP($A15,'Parts List and Volumes'!$C$2:$W206,17,FALSE),"") | AF15: =IFERROR(VLOOKUP($A15,'Parts List and Volumes'!$C$2:$W206,18,FALSE),"") | AG15: =IFERROR((($F15*AE15)/FourHeadAssumption),"") | AH15: =IFERROR((($F15*AF15)/FourHeadAssumption),"") | AI15: =IFERROR(VLOOKUP($A15,'Parts List and Volumes'!$C$2:$W206,19,FALSE),"") | AJ15: =IFERROR(VLOOKUP($A15,'Parts List and Volumes'!$C$2:$W206,20,FALSE),"") | AK15: =IFERROR((($F15*AI15)/FourHeadAssumption),"") | AL15: =IFERROR((($F15*AJ15)/FourHeadAssumption),"") | AM15: =IFERROR(VLOOKUP($A15,'Parts List and Volumes'!$C$2:$W206,21,FALSE),"") | AN15: =IFERROR(VLOOKUP($A15,'Parts List and Volumes'!$C$2:$W206,22,FALSE),"") | AO15: =IFERROR((($F15*AM15)/FourHeadAssumption),"") | AP15: =IFERROR((($F15*AN15)/FourHeadAssumption),"") | AQ15: =IFERROR(VLOOKUP($A15,'Parts List and Volumes'!$C$2:$W206,23,FALSE),"") | AR15: =IFERROR(VLOOKUP($A15,'Parts List and Volumes'!$C$2:$W206,24,FALSE),"") | AS15: =IFERROR((($F15*AQ15)/FourHeadAssumption),"") | AT15: =IFERROR((($F15*AR15)/FourHeadAssumption),"") | AU15: =IFERROR(VLOOKUP($A15,'Parts List and Volumes'!$C$2:$W206,25,FALSE),"") | AV15: =IFERROR(VLOOKUP($A15,'Parts List and Volumes'!$C$2:$W206,26,FALSE),"") | AW15: =IFERROR((($F15*AU15)/FourHeadAssumption),"") | AX15: =IFERROR((($F15*AV15)/FourHeadAssumption),"")
C16: =IFERROR(VLOOKUP(A16,'Parts List and Volumes'!C15:D207,2,FALSE),"") | D16: =IFERROR(IF(VLOOKUP($A16,'Parts List and Volumes'!$C15:$F270,3,FALSE)=0,"",VLOOKUP(A16,'Parts List and Volumes'!C15:F270,3,FALSE)),"") | E16: =IFERROR(IF(VLOOKUP($A16,'Parts List and Volumes'!$C15:$F270,4,FALSE)=0,"",VLOOKUP(B16,'Parts List and Volumes'!D15:G270,3,FALSE)),"") | G16: =IFERROR(VLOOKUP($A16,'Parts List and Volumes'!$C$2:$W207,5,FALSE),"") | H16: =IFERROR(VLOOKUP($A16,'Parts List and Volumes'!$C$2:$W207,6,FALSE),"") | I16: =IFERROR((($F16*G16)/FourHeadAssumption),"") | J16: =IFERROR((($F16*H16)/FourHeadAssumption),"") | K16: =IFERROR(VLOOKUP($A16,'Parts List and Volumes'!$C$2:$W207,7,FALSE),"") | L16: =IFERROR(VLOOKUP($A16,'Parts List and Volumes'!$C$2:$W207,8,FALSE),"") | M16: =IFERROR((($F16*K16)/FourHeadAssumption),"") | N16: =IFERROR((($F16*L16)/FourHeadAssumption),"") | O16: =IFERROR(VLOOKUP($A16,'Parts List and Volumes'!$C$2:$W207,9,FALSE),"") | P16: =IFERROR(VLOOKUP($A16,'Parts List and Volumes'!$C$2:$W207,10,FALSE),"") | Q16: =IFERROR((($F16*O16)/FourHeadAssumption),"") | R16: =IFERROR((($F16*P16)/FourHeadAssumption),"") | S16: =IFERROR(VLOOKUP($A16,'Parts List and Volumes'!$C$2:$W207,11,FALSE),"") | T16: =IFERROR(VLOOKUP($A16,'Parts List and Volumes'!$C$2:$W207,12,FALSE),"") | U16: =IFERROR((($F16*S16)/FourHeadAssumption),"") | V16: =IFERROR((($F16*T16)/FourHeadAssumption),"") | W16: =IFERROR(VLOOKUP($A16,'Parts List and Volumes'!$C$2:$W207,13,FALSE),"") | X16: =IFERROR(VLOOKUP($A16,'Parts List and Volumes'!$C$2:$W207,14,FALSE),"") | Y16: =IFERROR((($F16*W16)/FourHeadAssumption),"") | Z16: =IFERROR((($F16*X16)/FourHeadAssumption),"") | AA16: =IFERROR(VLOOKUP($A16,'Parts List and Volumes'!$C$2:$W207,15,FALSE),"") | AB16: =IFERROR(VLOOKUP($A16,'Parts List and Volumes'!$C$2:$W207,16,FALSE),"") | AC16: =IFERROR((($F16*AA16)/FourHeadAssumption),"") | AD16: =IFERROR((($F16*AB16)/FourHeadAssumption),"") | AE16: =IFERROR(VLOOKUP($A16,'Parts List and Volumes'!$C$2:$W207,17,FALSE),"") | AF16: =IFERROR(VLOOKUP($A16,'Parts List and Volumes'!$C$2:$W207,18,FALSE),"") | AG16: =IFERROR((($F16*AE16)/FourHeadAssumption),"") | AH16: =IFERROR((($F16*AF16)/FourHeadAssumption),"") | AI16: =IFERROR(VLOOKUP($A16,'Parts List and Volumes'!$C$2:$W207,19,FALSE),"") | AJ16: =IFERROR(VLOOKUP($A16,'Parts List and Volumes'!$C$2:$W207,20,FALSE),"") | AK16: =IFERROR((($F16*AI16)/FourHeadAssumption),"") | AL16: =IFERROR((($F16*AJ16)/FourHeadAssumption),"") | AM16: =IFERROR(VLOOKUP($A16,'Parts List and Volumes'!$C$2:$W207,21,FALSE),"") | AN16: =IFERROR(VLOOKUP($A16,'Parts List and Volumes'!$C$2:$W207,22,FALSE),"") | AO16: =IFERROR((($F16*AM16)/FourHeadAssumption),"") | AP16: =IFERROR((($F16*AN16)/FourHeadAssumption),"") | AQ16: =IFERROR(VLOOKUP($A16,'Parts List and Volumes'!$C$2:$W207,23,FALSE),"") | AR16: =IFERROR(VLOOKUP($A16,'Parts List and Volumes'!$C$2:$W207,24,FALSE),"") | AS16: =IFERROR((($F16*AQ16)/FourHeadAssumption),"") | AT16: =IFERROR((($F16*AR16)/FourHeadAssumption),"") | AU16: =IFERROR(VLOOKUP($A16,'Parts List and Volumes'!$C$2:$W207,25,FALSE),"") | AV16: =IFERROR(VLOOKUP($A16,'Parts List and Volumes'!$C$2:$W207,26,FALSE),"") | AW16: =IFERROR((($F16*AU16)/FourHeadAssumption),"") | AX16: =IFERROR((($F16*AV16)/FourHeadAssumption),"")
